2020-09-10 09:26:24,356 ERROR Exception on /admin/create_user [POST] [in %(lineno)d]
Traceback (most recent call last):
  File "/home/kukri/.local/lib/python3.6/site-packages/sqlalchemy/engine/base.py", line 1278, in _execute_context
    cursor, statement, parameters, context
  File "/home/kukri/.local/lib/python3.6/site-packages/sqlalchemy/engine/default.py", line 593, in do_execute
    cursor.execute(statement, parameters)
  File "/home/kukri/.local/lib/python3.6/site-packages/pymysql/cursors.py", line 163, in execute
    result = self._query(query)
  File "/home/kukri/.local/lib/python3.6/site-packages/pymysql/cursors.py", line 321, in _query
    conn.query(q)
  File "/home/kukri/.local/lib/python3.6/site-packages/pymysql/connections.py", line 505, in query
    self._affected_rows = self._read_query_result(unbuffered=unbuffered)
  File "/home/kukri/.local/lib/python3.6/site-packages/pymysql/connections.py", line 724, in _read_query_result
    result.read()
  File "/home/kukri/.local/lib/python3.6/site-packages/pymysql/connections.py", line 1069, in read
    first_packet = self.connection._read_packet()
  File "/home/kukri/.local/lib/python3.6/site-packages/pymysql/connections.py", line 676, in _read_packet
    packet.raise_for_error()
  File "/home/kukri/.local/lib/python3.6/site-packages/pymysql/protocol.py", line 223, in raise_for_error
    err.raise_mysql_exception(self._data)
  File "/home/kukri/.local/lib/python3.6/site-packages/pymysql/err.py", line 107, in raise_mysql_exception
    raise errorclass(errno, errval)
pymysql.err.IntegrityError: (1062, "Duplicate entry 'Kurki.Olli' for key 'ix_user_username'")

The above exception was the direct cause of the following exception:

Traceback (most recent call last):
  File "/home/kukri/.local/lib/python3.6/site-packages/flask/app.py", line 2447, in wsgi_app
    response = self.full_dispatch_request()
  File "/home/kukri/.local/lib/python3.6/site-packages/flask/app.py", line 1952, in full_dispatch_request
    rv = self.handle_user_exception(e)
  File "/home/kukri/.local/lib/python3.6/site-packages/flask/app.py", line 1821, in handle_user_exception
    reraise(exc_type, exc_value, tb)
  File "/home/kukri/.local/lib/python3.6/site-packages/flask/_compat.py", line 39, in reraise
    raise value
  File "/home/kukri/.local/lib/python3.6/site-packages/flask/app.py", line 1950, in full_dispatch_request
    rv = self.dispatch_request()
  File "/home/kukri/.local/lib/python3.6/site-packages/flask/app.py", line 1936, in dispatch_request
    return self.view_functions[rule.endpoint](**req.view_args)
  File "/home/kukri/.local/lib/python3.6/site-packages/flask_login/utils.py", line 272, in decorated_view
    return func(*args, **kwargs)
  File "/home/kukri/Janus/app/routes.py", line 105, in create_user
    db.session.flush()
  File "/home/kukri/.local/lib/python3.6/site-packages/sqlalchemy/orm/scoping.py", line 163, in do
    return getattr(self.registry(), name)(*args, **kwargs)
  File "/home/kukri/.local/lib/python3.6/site-packages/sqlalchemy/orm/session.py", line 2523, in flush
    self._flush(objects)
  File "/home/kukri/.local/lib/python3.6/site-packages/sqlalchemy/orm/session.py", line 2664, in _flush
    transaction.rollback(_capture_exception=True)
  File "/home/kukri/.local/lib/python3.6/site-packages/sqlalchemy/util/langhelpers.py", line 69, in __exit__
    exc_value, with_traceback=exc_tb,
  File "/home/kukri/.local/lib/python3.6/site-packages/sqlalchemy/util/compat.py", line 178, in raise_
    raise exception
  File "/home/kukri/.local/lib/python3.6/site-packages/sqlalchemy/orm/session.py", line 2624, in _flush
    flush_context.execute()
  File "/home/kukri/.local/lib/python3.6/site-packages/sqlalchemy/orm/unitofwork.py", line 422, in execute
    rec.execute(self)
  File "/home/kukri/.local/lib/python3.6/site-packages/sqlalchemy/orm/unitofwork.py", line 589, in execute
    uow,
  File "/home/kukri/.local/lib/python3.6/site-packages/sqlalchemy/orm/persistence.py", line 245, in save_obj
    insert,
  File "/home/kukri/.local/lib/python3.6/site-packages/sqlalchemy/orm/persistence.py", line 1136, in _emit_insert_statements
    statement, params
  File "/home/kukri/.local/lib/python3.6/site-packages/sqlalchemy/engine/base.py", line 1014, in execute
    return meth(self, multiparams, params)
  File "/home/kukri/.local/lib/python3.6/site-packages/sqlalchemy/sql/elements.py", line 298, in _execute_on_connection
    return connection._execute_clauseelement(self, multiparams, params)
  File "/home/kukri/.local/lib/python3.6/site-packages/sqlalchemy/engine/base.py", line 1133, in _execute_clauseelement
    distilled_params,
  File "/home/kukri/.local/lib/python3.6/site-packages/sqlalchemy/engine/base.py", line 1318, in _execute_context
    e, statement, parameters, cursor, context
  File "/home/kukri/.local/lib/python3.6/site-packages/sqlalchemy/engine/base.py", line 1512, in _handle_dbapi_exception
    sqlalchemy_exception, with_traceback=exc_info[2], from_=e
  File "/home/kukri/.local/lib/python3.6/site-packages/sqlalchemy/util/compat.py", line 178, in raise_
    raise exception
  File "/home/kukri/.local/lib/python3.6/site-packages/sqlalchemy/engine/base.py", line 1278, in _execute_context
    cursor, statement, parameters, context
  File "/home/kukri/.local/lib/python3.6/site-packages/sqlalchemy/engine/default.py", line 593, in do_execute
    cursor.execute(statement, parameters)
  File "/home/kukri/.local/lib/python3.6/site-packages/pymysql/cursors.py", line 163, in execute
    result = self._query(query)
  File "/home/kukri/.local/lib/python3.6/site-packages/pymysql/cursors.py", line 321, in _query
    conn.query(q)
  File "/home/kukri/.local/lib/python3.6/site-packages/pymysql/connections.py", line 505, in query
    self._affected_rows = self._read_query_result(unbuffered=unbuffered)
  File "/home/kukri/.local/lib/python3.6/site-packages/pymysql/connections.py", line 724, in _read_query_result
    result.read()
  File "/home/kukri/.local/lib/python3.6/site-packages/pymysql/connections.py", line 1069, in read
    first_packet = self.connection._read_packet()
  File "/home/kukri/.local/lib/python3.6/site-packages/pymysql/connections.py", line 676, in _read_packet
    packet.raise_for_error()
  File "/home/kukri/.local/lib/python3.6/site-packages/pymysql/protocol.py", line 223, in raise_for_error
    err.raise_mysql_exception(self._data)
  File "/home/kukri/.local/lib/python3.6/site-packages/pymysql/err.py", line 107, in raise_mysql_exception
    raise errorclass(errno, errval)
sqlalchemy.exc.IntegrityError: (pymysql.err.IntegrityError) (1062, "Duplicate entry 'Kurki.Olli' for key 'ix_user_username'")
[SQL: INSERT INTO user (username, password_hash, clearance, `group`, last_seen) VALUES (%(username)s, %(password_hash)s, %(clearance)s, %(group)s, %(last_seen)s)]
[parameters: {'username': 'Kurki.Olli', 'password_hash': 'pbkdf2:sha256:150000$wscwe4jq$577262d9d603919d6d610501e74a776831406df2857756a388157a7ae2fb1a34', 'clearance': 3, 'group': None, 'last_seen': datetime.datetime(2020, 9, 10, 6, 26, 24, 340618)}]
(Background on this error at: http://sqlalche.me/e/13/gkpj)
2020-09-10 09:28:01,049 INFO Janus sartup [in %(lineno)d]
